[2024-04-03T07:54:11.336+0000] {taskinstance.py:1979} INFO - Dependencies all met for dep_context=non-requeueable deps ti=<TaskInstance: dag_allocate_messages.select_and_allocate_messages scheduled__2024-04-02T00:00:00+00:00 [queued]>
[2024-04-03T07:54:11.355+0000] {taskinstance.py:1979} INFO - Dependencies all met for dep_context=requeueable deps ti=<TaskInstance: dag_allocate_messages.select_and_allocate_messages scheduled__2024-04-02T00:00:00+00:00 [queued]>
[2024-04-03T07:54:11.356+0000] {taskinstance.py:2193} INFO - Starting attempt 2 of 6
[2024-04-03T07:54:11.385+0000] {taskinstance.py:2214} INFO - Executing <Task(PythonOperator): select_and_allocate_messages> on 2024-04-02 00:00:00+00:00
[2024-04-03T07:54:11.394+0000] {standard_task_runner.py:60} INFO - Started process 726 to run task
[2024-04-03T07:54:11.403+0000] {standard_task_runner.py:87} INFO - Running: ['***', 'tasks', 'run', 'dag_allocate_messages', 'select_and_allocate_messages', 'scheduled__2024-04-02T00:00:00+00:00', '--job-id', '1207', '--raw', '--subdir', 'DAGS_FOLDER/dag_allocate_messages.py', '--cfg-path', '/tmp/tmphniqvpkg']
[2024-04-03T07:54:11.408+0000] {standard_task_runner.py:88} INFO - Job 1207: Subtask select_and_allocate_messages
[2024-04-03T07:54:11.492+0000] {task_command.py:423} INFO - Running <TaskInstance: dag_allocate_messages.select_and_allocate_messages scheduled__2024-04-02T00:00:00+00:00 [running]> on host af8488263d95
[2024-04-03T07:54:11.648+0000] {taskinstance.py:2510} INFO - Exporting env vars: AIRFLOW_CTX_DAG_OWNER='daniel' AIRFLOW_CTX_DAG_ID='dag_allocate_messages' AIRFLOW_CTX_TASK_ID='select_and_allocate_messages' AIRFLOW_CTX_EXECUTION_DATE='2024-04-02T00:00:00+00:00' AIRFLOW_CTX_TRY_NUMBER='2' AIRFLOW_CTX_DAG_RUN_ID='scheduled__2024-04-02T00:00:00+00:00'
[2024-04-03T07:54:11.668+0000] {base.py:83} INFO - Using connection ID 'postgres_localhost' for task execution.
[2024-04-03T07:54:11.721+0000] {taskinstance.py:2728} ERROR - Task failed with exception
Traceback (most recent call last):
  File "/home/airflow/.local/lib/python3.8/site-packages/airflow/models/taskinstance.py", line 444, in _execute_task
    result = _execute_callable(context=context, **execute_callable_kwargs)
  File "/home/airflow/.local/lib/python3.8/site-packages/airflow/models/taskinstance.py", line 414, in _execute_callable
    return execute_callable(context=context, **execute_callable_kwargs)
  File "/home/airflow/.local/lib/python3.8/site-packages/airflow/operators/python.py", line 200, in execute
    return_value = self.execute_callable()
  File "/home/airflow/.local/lib/python3.8/site-packages/airflow/operators/python.py", line 217, in execute_callable
    return self.python_callable(*self.op_args, **self.op_kwargs)
  File "/opt/airflow/dags/dag_allocate_messages.py", line 24, in select_and_allocate_messages
    insert_message(cursor, "success_messages", message)
  File "/opt/airflow/dags/dag_allocate_messages.py", line 45, in insert_message
    cursor.execute(
psycopg2.errors.UniqueViolation: duplicate key value violates unique constraint "success_messages_pkey"
DETAIL:  Key (msg_id)=(1) already exists.

[2024-04-03T07:54:11.735+0000] {taskinstance.py:1149} INFO - Marking task as UP_FOR_RETRY. dag_id=dag_allocate_messages, task_id=select_and_allocate_messages, execution_date=20240402T000000, start_date=20240403T075411, end_date=20240403T075411
[2024-04-03T07:54:11.755+0000] {standard_task_runner.py:107} ERROR - Failed to execute job 1207 for task select_and_allocate_messages (duplicate key value violates unique constraint "success_messages_pkey"
DETAIL:  Key (msg_id)=(1) already exists.
; 726)
[2024-04-03T07:54:11.777+0000] {local_task_job_runner.py:234} INFO - Task exited with return code 1
[2024-04-03T07:54:11.835+0000] {taskinstance.py:3309} INFO - 0 downstream tasks scheduled from follow-on schedule check
