[2024-04-03T09:14:48.377+0000] {taskinstance.py:1979} INFO - Dependencies all met for dep_context=non-requeueable deps ti=<TaskInstance: dag_allocate_messages.process_error_messages manual__2024-04-03T09:14:46.610489+00:00 [queued]>
[2024-04-03T09:14:48.405+0000] {taskinstance.py:1979} INFO - Dependencies all met for dep_context=requeueable deps ti=<TaskInstance: dag_allocate_messages.process_error_messages manual__2024-04-03T09:14:46.610489+00:00 [queued]>
[2024-04-03T09:14:48.407+0000] {taskinstance.py:2193} INFO - Starting attempt 1 of 6
[2024-04-03T09:14:48.444+0000] {taskinstance.py:2214} INFO - Executing <Task(PythonOperator): process_error_messages> on 2024-04-03 09:14:46.610489+00:00
[2024-04-03T09:14:48.468+0000] {standard_task_runner.py:60} INFO - Started process 9693 to run task
[2024-04-03T09:14:48.482+0000] {standard_task_runner.py:87} INFO - Running: ['***', 'tasks', 'run', 'dag_allocate_messages', 'process_error_messages', 'manual__2024-04-03T09:14:46.610489+00:00', '--job-id', '1231', '--raw', '--subdir', 'DAGS_FOLDER/dag_allocate_messages.py', '--cfg-path', '/tmp/tmpx2w6v2_e']
[2024-04-03T09:14:48.489+0000] {standard_task_runner.py:88} INFO - Job 1231: Subtask process_error_messages
[2024-04-03T09:14:48.612+0000] {task_command.py:423} INFO - Running <TaskInstance: dag_allocate_messages.process_error_messages manual__2024-04-03T09:14:46.610489+00:00 [running]> on host af8488263d95
[2024-04-03T09:14:48.855+0000] {taskinstance.py:2510} INFO - Exporting env vars: AIRFLOW_CTX_DAG_OWNER='daniel' AIRFLOW_CTX_DAG_ID='dag_allocate_messages' AIRFLOW_CTX_TASK_ID='process_error_messages' AIRFLOW_CTX_EXECUTION_DATE='2024-04-03T09:14:46.610489+00:00' AIRFLOW_CTX_TRY_NUMBER='1' AIRFLOW_CTX_DAG_RUN_ID='manual__2024-04-03T09:14:46.610489+00:00'
[2024-04-03T09:14:48.859+0000] {logging_mixin.py:188} INFO - proccess error messages
[2024-04-03T09:14:48.894+0000] {base.py:83} INFO - Using connection ID 'postgres_localhost' for task execution.
[2024-04-03T09:14:48.942+0000] {taskinstance.py:2728} ERROR - Task failed with exception
Traceback (most recent call last):
  File "/home/airflow/.local/lib/python3.8/site-packages/airflow/models/taskinstance.py", line 444, in _execute_task
    result = _execute_callable(context=context, **execute_callable_kwargs)
  File "/home/airflow/.local/lib/python3.8/site-packages/airflow/models/taskinstance.py", line 414, in _execute_callable
    return execute_callable(context=context, **execute_callable_kwargs)
  File "/home/airflow/.local/lib/python3.8/site-packages/airflow/operators/python.py", line 200, in execute
    return_value = self.execute_callable()
  File "/home/airflow/.local/lib/python3.8/site-packages/airflow/operators/python.py", line 217, in execute_callable
    return self.python_callable(*self.op_args, **self.op_kwargs)
  File "/opt/airflow/dags/dag_allocate_messages.py", line 67, in process_error_messages
    insert_message(cursor, "error_messages", message)
TypeError: insert_message() missing 1 required positional argument: 'category'
[2024-04-03T09:14:48.984+0000] {taskinstance.py:1149} INFO - Marking task as UP_FOR_RETRY. dag_id=dag_allocate_messages, task_id=process_error_messages, execution_date=20240403T091446, start_date=20240403T091448, end_date=20240403T091448
[2024-04-03T09:14:49.025+0000] {standard_task_runner.py:107} ERROR - Failed to execute job 1231 for task process_error_messages (insert_message() missing 1 required positional argument: 'category'; 9693)
[2024-04-03T09:14:49.059+0000] {local_task_job_runner.py:234} INFO - Task exited with return code 1
[2024-04-03T09:14:49.134+0000] {taskinstance.py:3309} INFO - 0 downstream tasks scheduled from follow-on schedule check
