[2024-04-02T14:09:43.207+0000] {taskinstance.py:1979} INFO - Dependencies all met for dep_context=non-requeueable deps ti=<TaskInstance: dag_allocate_messages.select_and_allocate_messages scheduled__2024-03-30T00:00:00+00:00 [queued]>
[2024-04-02T14:09:43.226+0000] {taskinstance.py:1979} INFO - Dependencies all met for dep_context=requeueable deps ti=<TaskInstance: dag_allocate_messages.select_and_allocate_messages scheduled__2024-03-30T00:00:00+00:00 [queued]>
[2024-04-02T14:09:43.226+0000] {taskinstance.py:2193} INFO - Starting attempt 6 of 6
[2024-04-02T14:09:43.261+0000] {taskinstance.py:2214} INFO - Executing <Task(PythonOperator): select_and_allocate_messages> on 2024-03-30 00:00:00+00:00
[2024-04-02T14:09:43.271+0000] {standard_task_runner.py:60} INFO - Started process 2727 to run task
[2024-04-02T14:09:43.284+0000] {standard_task_runner.py:87} INFO - Running: ['***', 'tasks', 'run', 'dag_allocate_messages', 'select_and_allocate_messages', 'scheduled__2024-03-30T00:00:00+00:00', '--job-id', '1182', '--raw', '--subdir', 'DAGS_FOLDER/dag_allocate_messages.py', '--cfg-path', '/tmp/tmpjiv415rk']
[2024-04-02T14:09:43.288+0000] {standard_task_runner.py:88} INFO - Job 1182: Subtask select_and_allocate_messages
[2024-04-02T14:09:43.363+0000] {task_command.py:423} INFO - Running <TaskInstance: dag_allocate_messages.select_and_allocate_messages scheduled__2024-03-30T00:00:00+00:00 [running]> on host 932f824b7ebb
[2024-04-02T14:09:43.469+0000] {taskinstance.py:2510} INFO - Exporting env vars: AIRFLOW_CTX_DAG_OWNER='daniel' AIRFLOW_CTX_DAG_ID='dag_allocate_messages' AIRFLOW_CTX_TASK_ID='select_and_allocate_messages' AIRFLOW_CTX_EXECUTION_DATE='2024-03-30T00:00:00+00:00' AIRFLOW_CTX_TRY_NUMBER='6' AIRFLOW_CTX_DAG_RUN_ID='scheduled__2024-03-30T00:00:00+00:00'
[2024-04-02T14:09:43.486+0000] {base.py:83} INFO - Using connection ID 'postgres_localhost' for task execution.
[2024-04-02T14:09:43.507+0000] {taskinstance.py:2728} ERROR - Task failed with exception
Traceback (most recent call last):
  File "/home/airflow/.local/lib/python3.8/site-packages/airflow/models/taskinstance.py", line 444, in _execute_task
    result = _execute_callable(context=context, **execute_callable_kwargs)
  File "/home/airflow/.local/lib/python3.8/site-packages/airflow/models/taskinstance.py", line 414, in _execute_callable
    return execute_callable(context=context, **execute_callable_kwargs)
  File "/home/airflow/.local/lib/python3.8/site-packages/airflow/operators/python.py", line 200, in execute
    return_value = self.execute_callable()
  File "/home/airflow/.local/lib/python3.8/site-packages/airflow/operators/python.py", line 217, in execute_callable
    return self.python_callable(*self.op_args, **self.op_kwargs)
  File "/opt/airflow/dags/dag_allocate_messages.py", line 21, in select_and_allocate_messages
    insert_message(cursor, "success_messages", message)
  File "/opt/airflow/dags/dag_allocate_messages.py", line 42, in insert_message
    cursor.execute(
psycopg2.errors.UniqueViolation: duplicate key value violates unique constraint "success_messages_pkey"
DETAIL:  Key (msg_id)=(1) already exists.

[2024-04-02T14:09:43.517+0000] {taskinstance.py:1149} INFO - Marking task as FAILED. dag_id=dag_allocate_messages, task_id=select_and_allocate_messages, execution_date=20240330T000000, start_date=20240402T140943, end_date=20240402T140943
[2024-04-02T14:09:43.537+0000] {standard_task_runner.py:107} ERROR - Failed to execute job 1182 for task select_and_allocate_messages (duplicate key value violates unique constraint "success_messages_pkey"
DETAIL:  Key (msg_id)=(1) already exists.
; 2727)
[2024-04-02T14:09:43.580+0000] {local_task_job_runner.py:234} INFO - Task exited with return code 1
[2024-04-02T14:09:43.608+0000] {taskinstance.py:3309} INFO - 0 downstream tasks scheduled from follow-on schedule check
